Workbook

Sheet Read Me
A1: Night Shift Gift Co. — Master Bundles (same layout as bounty_MASTER_bundles)
A3: Packaging: white box + white fill for mom, baby, shower and couples baskets. Black box + black fill for the dad baskets (NS-006, NS-007, NS-008).
A5: Tabs
A6: Night Shift Master Bundles — one row per component per basket. Unit cost pulls from New Components when blank.
A7: SumTracker Upload — Parent sku, component_sku, quantity. Upload once every NEW / Confirm SKU item exists in SumTracker.
A8: New Components — SKUs to create or confirm. Fill the yellow Unit Cost column; costs flow into every basket.
A9: Price Worksheet — cost roll-up per basket. Fill the yellow Target Margin and Your Price cells.
A10: Open Flags — decisions needed before upload.
A12: Colors: yellow = you fill in. Blue = hardcoded cost (Bounty master sheet, BroBasket cost sheet, or Shopify variant cost). Black = formula.
A13: Generated from catalog/recipes.json by catalog/build_bundles.py.

Sheet Night Shift Master Bundles
A1: Parent Name | B1: Parent sku | C1: Variant | D1: Packaging | E1: Component Name | F1: component_sku | G1: quantity | H1: Unit Cost ($) | I1: Line Total ($) | J1: Status
A2: Midnight Toast — Push Present Gift Set | B2: NS-001 | C2: Booze-free | D2: white small | E2: Fre Sparkling Brut Alcohol Removed | F2: AL-302 | G2: 1 | H2: 9 | I2: =IF(H2="","",G2*H2) -> 9 | J2: Existing
A3: Midnight Toast — Push Present Gift Set | B3: NS-001 | C3: Booze-free | D3: white small | E3: Champagne flute (engravable) | F3: ACC-NS-FLUTE | G3: 1 | H3: =IFERROR(IF(INDEX('New Components'!$E$2:$E$20,MATCH(F3,'New Components'!$A$2:$A$20,0))="","",INDEX('New Components'!$E$2:$E$20,MATCH(F3,'New Components'!$A$2:$A$20,0))),"") | I3: =IF(H3="","",G3*H3) | J3: NEW - create SKU
A4: Midnight Toast — Push Present Gift Set | B4: NS-001 | C4: Booze-free | D4: white small | E4: Ghirardelli Dark Chocolate Bars | F4: FD-041 | G4: 1 | H4: 3 | I4: =IF(H4="","",G4*H4) -> 3 | J4: Existing
A5: Midnight Toast — Push Present Gift Set | B5: NS-001 | C5: Booze-free | D5: white small | E5: Silk sleep mask | F5: ACC-NS-MASK | G5: 1 | H5: =IFERROR(IF(INDEX('New Components'!$E$2:$E$20,MATCH(F5,'New Components'!$A$2:$A$20,0))="","",INDEX('New Components'!$E$2:$E$20,MATCH(F5,'New Components'!$A$2:$A$20,0))),"") | I5: =IF(H5="","",G5*H5) | J5: NEW - create SKU
A6: Midnight Toast — Push Present Gift Set | B6: NS-001 | C6: Booze-free | D6: white small | E6: The Stroller Saver - Stroller Safety Leash | F6: SA-003 | G6: 1 | H6: 4 | I6: =IF(H6="","",G6*H6) -> 4 | J6: Lil & Mil
A7: Midnight Toast — Push Present Gift Set | B7: NS-001 | C7: Booze-free | D7: white small | E7: White Bounty Basket Box | F7: PKG-100 | G7: 1 | H7: 4.58 | I7: =IF(H7="","",G7*H7) -> 4.58 | J7: Existing
A8: Midnight Toast — Push Present Gift Set | B8: NS-001 | C8: Booze-free | D8: white small | E8: Krinkle Cut Fill | F8: PKG-059 | G8: 1 | H8: 0.5 | I8: =IF(H8="","",G8*H8) -> 0.5 | J8: Existing
A9: Midnight Toast — Push Present Gift Set | B9: NS-001 | C9: Booze-free | D9: white small | E9: Small Backer Board | F9: PKG-005 | G9: 1 | H9: 0.25 | I9: =IF(H9="","",G9*H9) -> 0.25 | J9: Existing
A10: Midnight Toast — Push Present Gift Set | B10: NS-001 | C10: Booze-free | D10: white small | E10: Small Shrink Wrap Bags | F10: PKG-073 | G10: 1 | H10: 0.33 | I10: =IF(H10="","",G10*H10) -> 0.33 | J10: Existing
A11: Midnight Toast — Push Present Gift Set | B11: NS-001-ALC | C11: With sparkling wine | D11: white small | E11: Champagne flute (engravable) | F11: ACC-NS-FLUTE | G11: 1 | H11: =IFERROR(IF(INDEX('New Components'!$E$2:$E$20,MATCH(F11,'New Components'!$A$2:$A$20,0))="","",INDEX('New Components'!$E$2:$E$20,MATCH(F11,'New Components'!$A$2:$A$20,0))),"") | I11: =IF(H11="","",G11*H11) | J11: NEW - create SKU
A12: Midnight Toast — Push Present Gift Set | B12: NS-001-ALC | C12: With sparkling wine | D12: white small | E12: Ghirardelli Dark Chocolate Bars | F12: FD-041 | G12: 1 | H12: 3 | I12: =IF(H12="","",G12*H12) -> 3 | J12: Existing
A13: Midnight Toast — Push Present Gift Set | B13: NS-001-ALC | C13: With sparkling wine | D13: white small | E13: Silk sleep mask | F13: ACC-NS-MASK | G13: 1 | H13: =IFERROR(IF(INDEX('New Components'!$E$2:$E$20,MATCH(F13,'New Components'!$A$2:$A$20,0))="","",INDEX('New Components'!$E$2:$E$20,MATCH(F13,'New Components'!$A$2:$A$20,0))),"") | I13: =IF(H13="","",G13*H13) | J13: NEW - create SKU
A14: Midnight Toast — Push Present Gift Set | B14: NS-001-ALC | C14: With sparkling wine | D14: white small | E14: The Stroller Saver - Stroller Safety Leash | F14: SA-003 | G14: 1 | H14: 4 | I14: =IF(H14="","",G14*H14) -> 4 | J14: Lil & Mil
A15: Midnight Toast — Push Present Gift Set | B15: NS-001-ALC | C15: With sparkling wine | D15: white small | E15: Mumm Sparkling Brut Prestige 750ml | F15: WINE-013 | G15: 1 | H15: 16.78 | I15: =IF(H15="","",G15*H15) -> 16.78 | J15: Existing
A16: Midnight Toast — Push Present Gift Set | B16: NS-001-ALC | C16: With sparkling wine | D16: white small | E16: White Bounty Basket Box | F16: PKG-100 | G16: 1 | H16: 4.58 | I16: =IF(H16="","",G16*H16) -> 4.58 | J16: Existing
A17: Midnight Toast — Push Present Gift Set | B17: NS-001-ALC | C17: With sparkling wine | D17: white small | E17: Krinkle Cut Fill | F17: PKG-059 | G17: 1 | H17: 0.5 | I17: =IF(H17="","",G17*H17) -> 0.5 | J17: Existing
A18: Midnight Toast — Push Present Gift Set | B18: NS-001-ALC | C18: With sparkling wine | D18: white small | E18: Small Backer Board | F18: PKG-005 | G18: 1 | H18: 0.25 | I18: =IF(H18="","",G18*H18) -> 0.25 | J18: Existing
A19: Midnight Toast — Push Present Gift Set | B19: NS-001-ALC | C19: With sparkling wine | D19: white small | E19: Small Shrink Wrap Bags | F19: PKG-073 | G19: 1 | H19: 0.33 | I19: =IF(H19="","",G19*H19) -> 0.33 | J19: Existing
A20: Off the Clock — Gifts for New Moms (Not for the Baby) | B20: NS-002 | C20: Booze-free | D20: white small | E20: Flower Market Rose Bath Bomb | F20: ACC-201 | G20: 1 | H20: 4 | I20: =IF(H20="","",G20*H20) -> 4 | J20: Existing
A21: Off the Clock — Gifts for New Moms (Not for the Baby) | B21: NS-002 | C21: Booze-free | D21: white small | E21: Biodance Bio-Collagen Facemask | F21: ACC-203 | G21: 1 | H21: 2.5 | I21: =IF(H21="","",G21*H21) -> 2.5 | J21: Existing
A22: Off the Clock — Gifts for New Moms (Not for the Baby) | B22: NS-002 | C22: Booze-free | D22: white small | E22: Ferrero Rocher 3pc | F22: FD-034 | G22: 2 | H22: 1.42 | I22: =IF(H22="","",G22*H22) -> 2.84 | J22: Existing
A23: Off the Clock — Gifts for New Moms (Not for the Baby) | B23: NS-002 | C23: Booze-free | D23: white small | E23: Cozy socks | F23: ACC-NS-SOCKS | G23: 1 | H23: =IFERROR(IF(INDEX('New Components'!$E$2:$E$20,MATCH(F23,'New Components'!$A$2:$A$20,0))="","",INDEX('New Components'!$E$2:$E$20,MATCH(F23,'New Components'!$A$2:$A$20,0))),"") | I23: =IF(H23="","",G23*H23) | J23: NEW - create SKU
A24: Off the Clock — Gifts for New Moms (Not for the Baby) | B24: NS-002 | C24: Booze-free | D24: white small | E24: Soy Wax Candle — Lavender Fields | F24: ACC-SPA-04 | G24: 1 | H24: 6 | I24: =IF(H24="","",G24*H24) -> 6 | J24: Existing
A25: Off the Clock — Gifts for New Moms (Not for the Baby) | B25: NS-002 | C25: Booze-free | D25: white small | E25: The Stroller Saver - Stroller Safety Leash | F25: SA-003 | G25: 1 | H25: 4 | I25: =IF(H25="","",G25*H25) -> 4 | J25: Lil & Mil
A26: Off the Clock — Gifts for New Moms (Not for the Baby) | B26: NS-002 | C26: Booze-free | D26: white small | E26: White Bounty Basket Box | F26: PKG-100 | G26: 1 | H26: 4.58 | I26: =IF(H26="","",G26*H26) -> 4.58 | J26: Existing
A27: Off the Clock — Gifts for New Moms (Not for the Baby) | B27: NS-002 | C27: Booze-free | D27: white small | E27: Krinkle Cut Fill | F27: PKG-059 | G27: 1 | H27: 0.5 | I27: =IF(H27="","",G27*H27) -> 0.5 | J27: Existing
A28: Off the Clock — Gifts for New Moms (Not for the Baby) | B28: NS-002 | C28: Booze-free | D28: white small | E28: Small Backer Board | F28: PKG-005 | G28: 1 | H28: 0.25 | I28: =IF(H28="","",G28*H28) -> 0.25 | J28: Existing
A29: Off the Clock — Gifts for New Moms (Not for the Baby) | B29: NS-002 | C29: Booze-free | D29: white small | E29: Small Shrink Wrap Bags | F29: PKG-073 | G29: 1 | H29: 0.33 | I29: =IF(H29="","",G29*H29) -> 0.33 | J29: Existing
A30: Off the Clock — Gifts for New Moms (Not for the Baby) | B30: NS-002-ALC | C30: With wine | D30: white small | E30: Flower Market Rose Bath Bomb | F30: ACC-201 | G30: 1 | H30: 4 | I30: =IF(H30="","",G30*H30) -> 4 | J30: Existing
A31: Off the Clock — Gifts for New Moms (Not for the Baby) | B31: NS-002-ALC | C31: With wine | D31: white small | E31: Biodance Bio-Collagen Facemask | F31: ACC-203 | G31: 1 | H31: 2.5 | I31: =IF(H31="","",G31*H31) -> 2.5 | J31: Existing
A32: Off the Clock — Gifts for New Moms (Not for the Baby) | B32: NS-002-ALC | C32: With wine | D32: white small | E32: Ferrero Rocher 3pc | F32: FD-034 | G32: 2 | H32: 1.42 | I32: =IF(H32="","",G32*H32) -> 2.84 | J32: Existing
A33: Off the Clock — Gifts for New Moms (Not for the Baby) | B33: NS-002-ALC | C33: With wine | D33: white small | E33: Cozy socks | F33: ACC-NS-SOCKS | G33: 1 | H33: =IFERROR(IF(INDEX('New Components'!$E$2:$E$20,MATCH(F33,'New Components'!$A$2:$A$20,0))="","",INDEX('New Components'!$E$2:$E$20,MATCH(F33,'New Components'!$A$2:$A$20,0))),"") | I33: =IF(H33="","",G33*H33) | J33: NEW - create SKU
A34: Off the Clock — Gifts for New Moms (Not for the Baby) | B34: NS-002-ALC | C34: With wine | D34: white small | E34: Soy Wax Candle — Lavender Fields | F34: ACC-SPA-04 | G34: 1 | H34: 6 | I34: =IF(H34="","",G34*H34) -> 6 | J34: Existing
A35: Off the Clock — Gifts for New Moms (Not for the Baby) | B35: NS-002-ALC | C35: With wine | D35: white small | E35: The Stroller Saver - Stroller Safety Leash | F35: SA-003 | G35: 1 | H35: 4 | I35: =IF(H35="","",G35*H35) -> 4 | J35: Lil & Mil
A36: Off the Clock — Gifts for New Moms (Not for the Baby) | B36: NS-002-ALC | C36: With wine | D36: white small | E36: Seaglass Pinot Noir | F36: WINE-001 | G36: 1 | H36: 12.08 | I36: =IF(H36="","",G36*H36) -> 12.08 | J36: Existing
A37: Off the Clock — Gifts for New Moms (Not for the Baby) | B37: NS-002-ALC | C37: With wine | D37: white small | E37: White Bounty Basket Box | F37: PKG-100 | G37: 1 | H37: 4.58 | I37: =IF(H37="","",G37*H37) -> 4.58 | J37: Existing
A38: Off the Clock — Gifts for New Moms (Not for the Baby) | B38: NS-002-ALC | C38: With wine | D38: white small | E38: Krinkle Cut Fill | F38: PKG-059 | G38: 1 | H38: 0.5 | I38: =IF(H38="","",G38*H38) -> 0.5 | J38: Existing
A39: Off the Clock — Gifts for New Moms (Not for the Baby) | B39: NS-002-ALC | C39: With wine | D39: white small | E39: Small Backer Board | F39: PKG-005 | G39: 1 | H39: 0.25 | I39: =IF(H39="","",G39*H39) -> 0.25 | J39: Existing
A40: Off the Clock — Gifts for New Moms (Not for the Baby) | B40: NS-002-ALC | C40: With wine | D40: white small | E40: Small Shrink Wrap Bags | F40: PKG-073 | G40: 1 | H40: 0.33 | I40: =IF(H40="","",G40*H40) -> 0.33 | J40: Existing
...

Sheet SumTracker Upload
A1: Parent sku | B1: component_sku | C1: quantity
A2: NS-001 | B2: AL-302 | C2: 1
A3: NS-001 | B3: ACC-NS-FLUTE | C3: 1
A4: NS-001 | B4: FD-041 | C4: 1
A5: NS-001 | B5: ACC-NS-MASK | C5: 1
A6: NS-001 | B6: SA-003 | C6: 1
A7: NS-001 | B7: PKG-100 | C7: 1
A8: NS-001 | B8: PKG-059 | C8: 1
A9: NS-001 | B9: PKG-005 | C9: 1
A10: NS-001 | B10: PKG-073 | C10: 1
A11: NS-001-ALC | B11: ACC-NS-FLUTE | C11: 1
A12: NS-001-ALC | B12: FD-041 | C12: 1
A13: NS-001-ALC | B13: ACC-NS-MASK | C13: 1
... A169: NS-013 | B169: PKG-073 | C169: 1

Sheet Price Worksheet
A1: Parent sku | B1: Parent Name | C1: Variant | D1: Known Cost ($) | E1: Components Missing Cost | F1: Target Margin | G1: Suggested Price ($) | H1: Your Price ($) | I1: Margin at Your Price
A2: NS-001 | B2: Midnight Toast — Push Present Gift Set | C2: Booze-free | D2: =SUMIFS('Night Shift Master Bundles'!$I$2:$I$169,'Night Shift Master Bundles'!$B$2:$B$169,A2) -> 21.66 | E2: =COUNTIFS('Night Shift Master Bundles'!$B$2:$B$169,A2,'Night Shift Master Bundles'!$H$2:$H$169,"") -> 2 | F2: 0.6 | G2: =IF(E2>0,"Fill costs first",IF(F2>=1,"",CEILING(D2/(1-F2),1)-0.05)) -> Fill costs first | I2: =IF(OR(H2="",H2=0),"",(H2-D2)/H2)
A3: NS-001-ALC | B3: Midnight Toast — Push Present Gift Set | C3: With sparkling wine | D3: =SUMIFS('Night Shift Master Bundles'!$I$2:$I$169,'Night Shift Master Bundles'!$B$2:$B$169,A3) -> 29.44 | E3: =COUNTIFS('Night Shift Master Bundles'!$B$2:$B$169,A3,'Night Shift Master Bundles'!$H$2:$H$169,"") -> 2 | F3: 0.6 | G3: =IF(E3>0,"Fill costs first",IF(F3>=1,"",CEILING(D3/(1-F3),1)-0.05)) -> Fill costs first | I3: =IF(OR(H3="",H3=0),"",(H3-D3)/H3)
A4: NS-002 | B4: Off the Clock — Gifts for New Moms (Not for the Baby) | C4: Booze-free | D4: =SUMIFS('Night Shift Master Bundles'!$I$2:$I$169,'Night Shift Master Bundles'!$B$2:$B$169,A4) -> 25 | E4: =COUNTIFS('Night Shift Master Bundles'!$B$2:$B$169,A4,'Night Shift Master Bundles'!$H$2:$H$169,"") -> 1 | F4: 0.6 | G4: =IF(E4>0,"Fill costs first",IF(F4>=1,"",CEILING(D4/(1-F4),1)-0.05)) -> Fill costs first | I4: =IF(OR(H4="",H4=0),"",(H4-D4)/H4)
A5: NS-002-ALC | B5: Off the Clock — Gifts for New Moms (Not for the Baby) | C5: With wine | D5: =SUMIFS('Night Shift Master Bundles'!$I$2:$I$169,'Night Shift Master Bundles'!$B$2:$B$169,A5) -> 37.08 | E5: =COUNTIFS('Night Shift Master Bundles'!$B$2:$B$169,A5,'Night Shift Master Bundles'!$H$2:$H$169,"") -> 1 | F5: 0.6 | G5: =IF(E5>0,"Fill costs first",IF(F5>=1,"",CEILING(D5/(1-F5),1)-0.05)) -> Fill costs first | I5: =IF(OR(H5="",H5=0),"",(H5-D5)/H5)
A6: NS-003 | B6: Recovery Shift — Postpartum Care Package | C6: Default | D6: =SUMIFS('Night Shift Master Bundles'!$I$2:$I$169,'Night Shift Master Bundles'!$B$2:$B$169,A6) -> 13.57 | E6: =COUNTIFS('Night Shift Master Bundles'!$B$2:$B$169,A6,'Night Shift Master Bundles'!$H$2:$H$169,"") -> 4 | F6: 0.6 | G6: =IF(E6>0,"Fill costs first",IF(F6>=1,"",CEILING(D6/(1-F6),1)-0.05)) -> Fill costs first | I6: =IF(OR(H6="",H6=0),"",(H6-D6)/H6)
A7: NS-004 | B7: The 3AM Feed — New Mom Gift Basket | C7: Default | D7: =SUMIFS('Night Shift Master Bundles'!$I$2:$I$169,'Night Shift Master Bundles'!$B$2:$B$169,A7) -> 14.99 | E7: =COUNTIFS('Night Shift Master Bundles'!$B$2:$B$169,A7,'Night Shift Master Bundles'!$H$2:$H$169,"") -> 3 | F7: 0.6 | G7: =IF(E7>0,"Fill costs first",IF(F7>=1,"",CEILING(D7/(1-F7),1)-0.05)) -> Fill costs first | I7: =IF(OR(H7="",H7=0),"",(H7-D7)/H7)
A8: NS-005 | B8: Before the Night Shift — Mom-to-Be Gift Box | C8: Default | D8: =SUMIFS('Night Shift Master Bundles'!$I$2:$I$169,'Night Shift Master Bundles'!$B$2:$B$169,A8) -> 15.39 | E8: =COUNTIFS('Night Shift Master Bundles'!$B$2:$B$169,A8,'Night Shift Master Bundles'!$H$2:$H$169,"") -> 3 | F8: 0.6 | G8: =IF(E8>0,"Fill costs first",IF(F8>=1,"",CEILING(D8/(1-F8),1)-0.05)) -> Fill costs first | I8: =IF(OR(H8="",H8=0),"",(H8-D8)/H8)
A9: NS-006 | B9: Graveyard Shift Survival Kit — New Dad Gift | C9: Booze-free | D9: =SUMIFS('Night Shift Master Bundles'!$I$2:$I$169,'Night Shift Master Bundles'!$B$2:$B$169,A9) -> 25.99 | E9: =COUNTIFS('Night Shift Master Bundles'!$B$2:$B$169,A9,'Night Shift Master Bundles'!$H$2:$H$169,"") -> 2 | F9: 0.6 | G9: =IF(E9>0,"Fill costs first",IF(F9>=1,"",CEILING(D9/(1-F9),1)-0.05)) -> Fill costs first | I9: =IF(OR(H9="",H9=0),"",(H9-D9)/H9)
A10: NS-006-ALC | B10: Graveyard Shift Survival Kit — New Dad Gift | C10: With craft beer | D10: =SUMIFS('Night Shift Master Bundles'!$I$2:$I$169,'Night Shift Master Bundles'!$B$2:$B$169,A10) -> 25.99 | E10: =COUNTIFS('Night Shift Master Bundles'!$B$2:$B$169,A10,'Night Shift Master Bundles'!$H$2:$H$169,"") -> 2 | F10: 0.6 | G10: =IF(E10>0,"Fill costs first",IF(F10>=1,"",CEILING(D10/(1-F10),1)-0.05)) -> Fill costs first | I10: =IF(OR(H10="",H10=0),"",(H10-D10)/H10)
A11: NS-007 | B11: Nightcap — First-Time Dad Gift | C11: Booze-free | D11: =SUMIFS('Night Shift Master Bundles'!$I$2:$I$169,'Night Shift Master Bundles'!$B$2:$B$169,A11) -> 15.18 | E11: =COUNTIFS('Night Shift Master Bundles'!$B$2:$B$169,A11,'Night Shift Master Bundles'!$H$2:$H$169,"") -> 0 | F11: 0.6 | G11: =IF(E11>0,"Fill costs first",IF(F11>=1,"",CEILING(D11/(1-F11),1)-0.05)) -> 37.95 | I11: =IF(OR(H11="",H11=0),"",(H11-D11)/H11)
A12: NS-007-ALC | B12: Nightcap — First-Time Dad Gift | C12: With whiskey | D12: =SUMIFS('Night Shift Master Bundles'!$I$2:$I$169,'Night Shift Master Bundles'!$B$2:$B$169,A12) -> 12.08 | E12: =COUNTIFS('Night Shift Master Bundles'!$B$2:$B$169,A12,'Night Shift Master Bundles'!$H$2:$H$169,"") -> 1 | F12: 0.6 | G12: =IF(E12>0,"Fill costs first",IF(F12>=1,"",CEILING(D12/(1-F12),1)-0.05)) -> Fill costs first | I12: =IF(OR(H12="",H12=0),"",(H12-D12)/H12)
A13: NS-008 | B13: Night Shift Dad — Diaper Duty Gift Pack | C13: Default | D13: =SUMIFS('Night Shift Master Bundles'!$I$2:$I$169,'Night Shift Master Bundles'!$B$2:$B$169,A13) -> 20.31 | E13: =COUNTIFS('Night Shift Master Bundles'!$B$2:$B$169,A13,'Night Shift Master Bundles'!$H$2:$H$169,"") -> 1 | F13: 0.6 | G13: =IF(E13>0,"Fill costs first",IF(F13>=1,"",CEILING(D13/(1-F13),1)-0.05)) -> Fill costs first | I13: =IF(OR(H13="",H13=0),"",(H13-D13)/H13)
... A19: NS-013 | B19: Double Shift — Mom & Baby Gift Set | C19: Default | D19: =SUMIFS('Night Shift Master Bundles'!$I$2:$I$169,'Night Shift Master Bundles'!$B$2:$B$169,A19) -> 24.76 | E19: =COUNTIFS('Night Shift Master Bundles'!$B$2:$B$169,A19,'Night Shift Master Bundles'!$H$2:$H$169,"") -> 0 | F19: 0.6 | G19: =IF(E19>0,"Fill costs first",IF(F19>=1,"",CEILING(D19/(1-F19),1)-0.05)) -> 61.95 | I19: =IF(OR(H19="",H19=0),"",(H19-D19)/H19)

Sheet New Components
A1: component_sku | B1: Component Name | C1: Status | D1: Used in (parent skus) | E1: Unit Cost ($) | F1: Notes
A2: ACC-GAME-CARDS | B2: Card / Mini Game Set | C2: Placeholder - not in SumTracker | D2: NS-009, NS-009-ALC | F2: Listed in the Bounty sheet but not in SumTracker
A3: ACC-MUG-PAIR | B3: Ceramic Mug Pair | C3: Placeholder - not in SumTracker | D3: NS-010 | F3: Listed in the Bounty sheet but not in SumTracker
A4: ACC-NS-BELLYBUTTER | B4: Belly butter | C4: NEW - create SKU | D4: NS-005
A5: ACC-NS-BIBS | B5: Baby bibs (2pk) | C5: NEW - create SKU | D5: NS-012
A6: ACC-NS-BOARDBOOK | B6: Baby board book | C6: NEW - create SKU | D6: NS-012
A7: ACC-NS-DRYSHAMPOO | B7: Dry shampoo | C7: NEW - create SKU | D7: NS-003
A8: ACC-NS-FLUTE | B8: Champagne flute (engravable) | C8: NEW - create SKU | D8: NS-001, NS-001-ALC
A9: ACC-NS-LIPBALM | B9: Lip balm | C9: NEW - create SKU | D9: NS-003
A10: ACC-NS-MASK | B10: Silk sleep mask | C10: NEW - create SKU | D10: NS-001, NS-001-ALC
A11: ACC-NS-NIGHTLIGHT | B11: Portable night-light | C11: NEW - create SKU | D11: NS-004
A12: ACC-NS-ROBE | B12: Soft throw or robe | C12: NEW - create SKU | D12: NS-003
A13: ACC-NS-SOCKS | B13: Cozy socks | C13: NEW - create SKU | D13: NS-002, NS-002-ALC, NS-005
A14: ACC-NS-TUMBLER | B14: Insulated tumbler | C14: NEW - create SKU | D14: NS-003, NS-004
A15: AL-TBD-WHISKEY | B15: Whiskey (pick BroBasket SKU) | C15: NEW - create SKU | D15: NS-007-ALC
... A19: MXR-NS-ROOTBEER | B19: Craft root beer 12oz | C19: NEW - create SKU | D19: NS-006
A20: PKG-BOX-BLACK-L | B20: Large black gift box (confirm SKU) | C20: Confirm SKU | D20: NS-006, NS-006-ALC, NS-008 | F20: You stock this already — replace with the real SKU in recipes.json

Sheet Open Flags
A1: Check | B1: Detail
A2: Packaging SKUs to confirm | B2: Every basket uses PKG-059 Krinkle Cut Fill ($0.50) — one fill SKU regardless of color (James, Sep 16). Small black box = PKG-082. The large black box exists in SumTracker but its SKU was not in the Bounty or BroBasket sheets: placeholder PKG-BOX-BLACK-L until confirmed.
A3: Box size | B3: White baskets use PKG-100 White Bounty Basket Box ($4.58). NS-003, NS-005 and NS-011 carry the Tot Tote or a robe — confirm PKG-100 fits or add a larger white box SKU. Dad baskets NS-006 and NS-008 need the large black box; NS-007 uses PKG-082 Small Black Box ($1.00).
A4: Couples baskets | B4: NS-009 Lights Out Date Night and NS-010 The Morning After are packed white. Switch them to black in recipes.json if you'd rather.
A5: Lil & Mil SKUs in SumTracker | B5: SA-003, SA-002, SA-005, TA-001, 2000, 1010 must exist in SumTracker with correct stock before uploading recipes.
A6: Alcohol variants (-ALC) | B6: Upload -ALC recipes only once it is decided which store sells alcohol baskets. BEER-TBD and AL-TBD-WHISKEY need real SKUs.
A7: Zero-proof sparkling | B7: AL-302 Fre Sparkling Brut Alcohol Removed ($9.00) in NS-001 and NS-009.
A8: Pregnancy-safe items (NS-005) | B8: ACC-203 face mask is in the Mom-to-Be box — confirm it is suitable in pregnancy.
A9: Cup and plate colors | B9: Recipes use Black (2000 cup, 1010 plates). Only ~39 plate sets remain.
A10: Bounty placeholders reused | B10: ACC-GAME-CARDS (NS-009) and ACC-MUG-PAIR (NS-010) are in the Bounty sheet but not in SumTracker.
